<?xml version="1.0" encoding="utf-8"?>
<robot name="sabby_robby" xmlns:xacro="http://www.ros.org/wiki/xacro" >

  <xacro:include filename="sabby_robby_gazebo.xacro"/>
  <xacro:include filename="camera.xacro"/>
  
  <material name="blue">
    <color rgba="0 0.3 0.7 1" />
  </material>

  <material name="bluered">
    <color rgba="0.8 0.2 0.7 1" />
  </material>

  <material name="greenblue">
    <color rgba="0 0.8 0.8 1" />
  </material>
  
  <link name="base_link">
    <inertial>
      <origin xyz="-0.0393804438397903 -4.9960036108132E-16 -1" rpy="0 0 0" />
      <mass value="4.15509198061297" />
      <inertia ixx="0.104793677550994" ixy="4.34625011283321E-16" ixz="-0.0160644282903705" iyy="0.18635846427725" iyz="-7.22920717246174E-17" izz="0.249707323070578" />
    </inertial>
    <visual>
      <origin xyz="0 0 0" rpy="0 0 0" />
      <geometry>
        <mesh filename="file://$(find sabby_robby)/meshes/base_link.STL" />
      </geometry>
      <material name="blue">
        
      </material>
    </visual>
    <collision>
      <origin xyz="0 0 0" rpy="0 0 0" />
      <geometry>
        <mesh filename="file://$(find sabby_robby)/meshes/base_link.STL" />
      </geometry>
    </collision>
  </link>

  <link name="base_footprint">

    </link>

    <joint name="base_joint" type="fixed">
        <parent link="base_footprint" />
        <child link="base_link" />
        <origin xyz="0 0 0.24" rpy="0 0 0" />
    </joint>
  
  <link name="link_FL">
    <inertial>
      <origin xyz="1.66533453693773E-16 -0.0399260258882922 0" rpy="0 0 0" />
      <mass value="5.98332477085146" />
      <inertia ixx="0.038931465954269" ixy="-1.14525968916749E-16" ixz="7.60561910381101E-37" iyy="0.0715693202976591" iyz="5.96532188894504E-35" izz="0.038931465954269" />
    </inertial>
    <visual>
      <origin xyz="0 0 0" rpy="0 0 0" />
      <geometry>
        <mesh filename="file://$(find sabby_robby)/meshes/link_FL.STL" />
      </geometry>
      <material name="bluered">
        
      </material>
    </visual>
    <collision>
      <origin xyz="0 0 0" rpy="0 0 0" />
      <geometry>
        <mesh filename="file://$(find sabby_robby)/meshes/link_FL.STL" />
      </geometry>
    </collision>
  </link>

  <joint name="joint_FL" type="continuous">
    <origin xyz="0.193 0.3 -0.0915" rpy="0 0 0" />
    <parent link="base_link" />
    <child link="link_FL" />
    <axis xyz="0 1 0" />
    <dynamics damping="0.7" />
  </joint>
  
  <link name="link_BL">
    <inertial>
      <origin xyz="-0.0104554020005766 2.73395611782301E-05 0.0142270479543802" rpy="0 0 0" />
      <mass value="0.0501520796182236" />
      <inertia ixx="4.63540269637638E-06" ixy="-3.51568213438317E-10" ixz="2.48064446383539E-07" iyy="5.07357918819359E-06" iyz="1.15130721361476E-10" izz="7.75969429784855E-06" />
    </inertial>
    <visual>
      <origin xyz="0 0 0" rpy="0 0 0" />
      <geometry>
        <mesh filename="file://$(find sabby_robby)/meshes/link_BL.STL" />
      </geometry>
      <material name="bluered">
        
      </material>
    </visual>
    <collision>
      <origin xyz="0 0 0" rpy="0 0 0" />
      <geometry>
        <mesh filename="file://$(find sabby_robby)/meshes/link_BL.STL" />
      </geometry>
    </collision>
  </link>

  <joint name="joint_BL" type="fixed">
    <origin xyz="-0.23299 0.16014 -0.23256" rpy="0 0 0.0094354" />
    <parent link="base_link" />
    <child link="link_BL" />
    <axis xyz="0 0 0" />
  </joint>
  
  <link name="link_FR">
    <inertial>
      <origin xyz="5.55111512312578E-17 0.0399260258882923 0" rpy="0 0 0" />
      <mass value="5.98332477085147" />
      <inertia ixx="0.0389314659542691" ixy="-9.32104990390014E-19" ixz="4.01934945428023E-18" iyy="0.0715693202976591" iyz="-3.54031090859653E-18" izz="0.0389314659542691" />
    </inertial>
    <visual>
      <origin xyz="0 0 0" rpy="0 0 0" />
      <geometry>
        <mesh filename="file://$(find sabby_robby)/meshes/link_FR.STL" />
      </geometry>
      <material name="bluered">
        
      </material>
    </visual>
    <collision>
      <origin xyz="0 0 0" rpy="0 0 0" />
      <geometry>
        <mesh filename="file://$(find sabby_robby)/meshes/link_FR.STL" />
      </geometry>
    </collision>
  </link>

  <joint name="joint_FR" type="continuous">
    <origin xyz="0.193 -0.3 -0.0915" rpy="0 0 0" />
    <parent link="base_link" />
    <child link="link_FR" />
    <axis xyz="0 1 0" />
    <dynamics damping="0.7" />
  </joint>
  
  <link name="link_BR">
    <inertial>
      <origin xyz="-0.0104551945572823 -7.13106909289163E-05 0.01422704795438" rpy="0 0 0" />
      <mass value="0.0501520796182244" />
      <inertia ixx="4.63544833829345E-06" ixy="-4.48561390456279E-09" ixz="2.48052318082788E-07" iyy="5.07353354627666E-06" iyz="2.45566862776434E-09" izz="7.75969429784863E-06" />
    </inertial>
    <visual>
      <origin xyz="0 0 0" rpy="0 0 0" />
      <geometry>
        <mesh filename="file://$(find sabby_robby)/meshes/link_BR.STL" />
      </geometry>
      <material name="bluered">
        
      </material>
    </visual>
    <collision>
      <origin xyz="0 0 0" rpy="0 0 0" />
      <geometry>
        <mesh filename="file://$(find sabby_robby)/meshes/link_BR.STL" />
      </geometry>
    </collision>
  </link>

   <joint name="joint_BR" type="fixed">
    <origin xyz="-0.23299 -0.15986 -0.23256" rpy="0 0 0" />
    <parent link="base_link" />
    <child link="link_BR" />
    <axis xyz="0 0 0" />
  </joint>
  
</robot>